<?xml version="1.0"?>
<robot name="myrobot">

  <gazebo>
    <plugin filename="libgazebo_ros2_control.so" name="gazebo_ros2_control">
      <robot_param>robot_description</robot_param>
      <robot_param_node>robot_state_publisher</robot_param_node>
      <parameters>/home/ty/f1test_ws/ar-tu-do/control_config.yaml</parameters>
    </plugin>
  </gazebo>

  <ros2_control name="GazeboSystem" type="system">
    <hardware>
      <plugin>gazebo_ros2_control/GazeboSystem</plugin>
    </hardware>
    <joint name="left_wheel_back_hinge">
      <command_interface name="velocity">
        <param name="min">-100</param>
        <param name="max">100</param>
      </command_interface>
      <state_interface name="position"/>
      <state_interface name="velocity"/>
    </joint>
    <joint name="right_wheel_back_hinge">
      <command_interface name="velocity">
        <param name="min">-100</param>
        <param name="max">100</param>
      </command_interface>
      <state_interface name="position"/>
      <state_interface name="velocity"/>
    </joint>
    <joint name="left_steering_hinge">
      <command_interface name="position">
        <param name="min">-1.0</param>
        <param name="max">1.0</param>
      </command_interface>
      <state_interface name="position"/>
      <state_interface name="velocity"/>
    </joint>
    <joint name="right_steering_hinge">
      <command_interface name="position">
        <param name="min">-1.0</param>
        <param name="max">1.0</param>
      </command_interface>
      <state_interface name="position"/>
      <state_interface name="velocity"/>
    </joint>
  </ros2_control>

  <gazebo reference="camera">
    <sensor name="camera1" type="camera">
      <update_rate>30.0</update_rate>
      <camera name="head">
        <horizontal_fov>1.3962634</horizontal_fov>
        <image>
          <width>800</width>
          <height>800</height>
          <format>R8G8B8</format>
        </image>
        <clip>
          <near>0.02</near>
          <far>300</far>
        </clip>
      </camera>
      <plugin filename="libgazebo_ros_camera.so" name="camera_controller">
        <alwaysOn>true</alwaysOn>
        <updateRate>0.0</updateRate>
        <cameraName>racer/camera1</cameraName>
        <imageTopicName>image_raw</imageTopicName>
        <cameraInfoTopicName>camera_info</cameraInfoTopicName>
        <frameName>camera</frameName>
        <hackBaseline>0.07</hackBaseline>
        <distortionK1>0.0</distortionK1>
        <distortionK2>0.0</distortionK2>
        <distortionK3>0.0</distortionK3>
        <distortionT1>0.0</distortionT1>
        <distortionT2>0.0</distortionT2>
      </plugin>
    </sensor>
  </gazebo>
  <gazebo reference="laser">
    <sensor name="laser_Scanner" type="gpu_ray">
      <pose>0 0 0 0 0 0</pose>
      <visualize>false</visualize>
      <update_rate>60</update_rate>
      <ray>
        <scan>
          <horizontal>
            <samples>1080</samples>
            <resolution>1</resolution>
            <min_angle>-2.35619</min_angle>
            <max_angle>2.35619</max_angle>
          </horizontal>
        </scan>
        <range>
          <min>0.2</min>
          <max>30.0</max>
          <resolution>0.01</resolution>
        </range>
        <noise>
          <type>gaussian</type>
          <mean>0.0</mean>
          <stddev>0.01</stddev>
        </noise>
      </ray>
      <plugin filename="libgazebo_ros_gpu_laser.so" name="gazebo_ros_head_hokuyo_controller">
        <topicName>/scan</topicName>
        <frameName>laser</frameName>
      </plugin>
    </sensor>
  </gazebo>
  <gazebo reference="imu_link">
    <gravity>true</gravity>
    <sensor name="imu_sensor" type="imu">
      <always_on>true</always_on>
      <update_rate>200</update_rate>
      <visualize>true</visualize>
      <topic>__default_topic__</topic>
      <plugin filename="libgazebo_ros_imu_sensor.so" name="imu_plugin">
        <topicName>imu</topicName>
        <bodyName>imu_link</bodyName>
        <updateRateHZ>100.0</updateRateHZ>
        <gaussianNoise>0.0</gaussianNoise>
        <xyzOffset>0 0 0</xyzOffset>
        <rpyOffset>0 0 0</rpyOffset>
        <frameName>imu_link</frameName>
      </plugin>
      <pose>0 0 0 0 0 0</pose>
    </sensor>
  </gazebo>

  <link name="base_link"/>
  <joint name="base_link_joint" type="fixed">
    <origin rpy="0 0 0" xyz="0 0 0.05"/>
    <parent link="base_link"/>
    <child link="chassis"/>
  </joint>

  <link name="chassis">
    <inertial>
      <mass value="3.5"/>
      <origin rpy=" 0 0 0" xyz="0 0 0.0225"/>
      <inertia ixx="0.012366666666666666" ixy="0" ixz="0" iyy="0.07294583333333333" iyz="0" izz="0.07947916666666666"/>
    </inertial>
    <collision name="collision">
      <origin rpy=" 0 0 0" xyz="0 0 0.0225"/>
      <geometry>
        <box size="0.49 0.18 0.1"/>
      </geometry>
    </collision>
    <visual>
      <origin rpy=" 0 0 0" xyz="0 0 0"/>
      <geometry>
        <mesh filename="file:///home/ty/f1test_ws/ar-tu-do/ros_ws/install/racer_description/share/racer_description/meshes/car.dae"/>
      </geometry>
      <material name="car_material">
        <color rgba="1.0 0.5 0.0 1.0"/>
      </material>
    </visual>
  </link>
  <gazebo reference="chassis">
    <material>Gazebo/Orange</material>
  </gazebo>

  <joint name="base_body_joint" type="fixed">
    <origin rpy="0 0 0" xyz="0 0 0"/>
    <parent link="base_link"/>
    <child link="body"/>
  </joint>
  <link name="body">
    <visual>
      <origin rpy=" 0 0 0" xyz="0 0 0.05"/>
      <geometry>
        <mesh filename="file:///home/ty/f1test_ws/ar-tu-do/ros_ws/install/racer_description/share/racer_description/meshes/body.dae"/>
      </geometry>
    </visual>
  </link>
  <gazebo reference="body">
    <material>Gazebo/Blue</material>
  </gazebo>

  <link name="left_wheel_front">
    <inertial>
      <mass value="0.2"/>
      <origin rpy="1.5707963267948966 0 0" xyz="0 0.02 0"/>
      <inertia ixx="0.00015875000000000004" ixy="0" ixz="0" iyy="0.00015875000000000004" iyz="0" izz="0.00025000000000000006"/>
    </inertial>
    <collision>
      <origin rpy="1.5707963267948966 0 0 " xyz="0 0.02 0"/>
      <geometry>
        <cylinder length="0.045" radius="0.05"/>
      </geometry>
    </collision>
    <visual>
      <origin rpy="0 0 3.141592653589793" xyz="0 0.02 0"/>
      <geometry>
        <mesh filename="file:///home/ty/f1test_ws/ar-tu-do/ros_ws/install/racer_description/share/racer_description/meshes/wheel.dae"/>
      </geometry>
    </visual>
  </link>
  <gazebo reference="left_wheel_front">
    <material>Gazebo/Black</material>
  </gazebo>
  <joint name="left_wheel_front_hinge" type="continuous">
    <parent link="left_steering"/>
    <child link="left_wheel_front"/>
    <origin rpy="0 0 0" xyz="0.0 0.001 0"/>
    <axis rpy="0 0 0" xyz="0 1 0"/>
    <limit effort="20" velocity="500"/>
    <joint_properties damping="0.0" friction="0.0"/>
  </joint>
  <transmission name="left_wheel_front_transmission">
    <type>transmission_interface/SimpleTransmission</type>
    <joint name="left_wheel_front_hinge">
      <hardwareInterface>hardware_interface/EffortJointInterface</hardwareInterface>
    </joint>
    <actuator name="left_wheel_front_motor">
      <hardwareInterface>hardware_interface/EffortJointInterface</hardwareInterface>
      <mechanicalReduction>1</mechanicalReduction>
    </actuator>
  </transmission>
  <gazebo reference="left_wheel_front">
    <mu1>0.9</mu1>
    <mu2>0.9</mu2>
  </gazebo>

  <link name="right_wheel_front">
    <inertial>
      <mass value="0.2"/>
      <origin rpy="1.5707963267948966 0 0" xyz="0 -0.02 0"/>
      <inertia ixx="0.00015875000000000004" ixy="0" ixz="0" iyy="0.00015875000000000004" iyz="0" izz="0.00025000000000000006"/>
    </inertial>
    <collision>
      <origin rpy="1.5707963267948966 0 0 " xyz="0 -0.02 0"/>
      <geometry>
        <cylinder length="0.045" radius="0.05"/>
      </geometry>
    </collision>
    <visual>
      <origin rpy="0 0 0.0" xyz="0 -0.02 0"/>
      <geometry>
        <mesh filename="file:///home/ty/f1test_ws/ar-tu-do/ros_ws/install/racer_description/share/racer_description/meshes/wheel.dae"/>
      </geometry>
    </visual>
  </link>
  <gazebo reference="right_wheel_front">
    <material>Gazebo/Black</material>
  </gazebo>
  <joint name="right_wheel_front_hinge" type="continuous">
    <parent link="right_steering"/>
    <child link="right_wheel_front"/>
    <origin rpy="0 0 0" xyz="0.0 -0.001 0"/>
    <axis rpy="0 0 0" xyz="0 1 0"/>
    <limit effort="20" velocity="500"/>
    <joint_properties damping="0.0" friction="0.0"/>
  </joint>
  <transmission name="right_wheel_front_transmission">
    <type>transmission_interface/SimpleTransmission</type>
    <joint name="right_wheel_front_hinge">
      <hardwareInterface>hardware_interface/EffortJointInterface</hardwareInterface>
    </joint>
    <actuator name="right_wheel_front_motor">
      <hardwareInterface>hardware_interface/EffortJointInterface</hardwareInterface>
      <mechanicalReduction>1</mechanicalReduction>
    </actuator>
  </transmission>
  <gazebo reference="right_wheel_front">
    <mu1>0.9</mu1>
    <mu2>0.9</mu2>
  </gazebo>

  <link name="left_wheel_back">
    <inertial>
      <mass value="0.2"/>
      <origin rpy="1.5707963267948966 0 0" xyz="0 0.021 0"/>
      <inertia ixx="0.00015875000000000004" ixy="0" ixz="0" iyy="0.00015875000000000004" iyz="0" izz="0.00025000000000000006"/>
    </inertial>
    <collision>
      <origin rpy="1.5707963267948966 0 0 " xyz="0 0.021 0"/>
      <geometry>
        <cylinder length="0.045" radius="0.05"/>
      </geometry>
    </collision>
    <visual>
      <origin rpy="0 0 3.141592653589793" xyz="0 0.021 0"/>
      <geometry>
        <mesh filename="file:///home/ty/f1test_ws/ar-tu-do/ros_ws/install/racer_description/share/racer_description/meshes/wheel.dae"/>
      </geometry>
    </visual>
  </link>
  <gazebo reference="left_wheel_back">
    <material>Gazebo/Black</material>
  </gazebo>
  <joint name="left_wheel_back_hinge" type="continuous">
    <parent link="chassis"/>
    <child link="left_wheel_back"/>
    <origin rpy="0 0 0" xyz="-0.16 0.1055 0"/>
    <axis rpy="0 0 0" xyz="0 1 0"/>
    <limit effort="20" velocity="500"/>
    <joint_properties damping="0.0" friction="0.0"/>
  </joint>
  <transmission name="left_wheel_back_transmission">
    <type>transmission_interface/SimpleTransmission</type>
    <joint name="left_wheel_back_hinge">
      <hardwareInterface>hardware_interface/VelocityJointInterface</hardwareInterface>
    </joint>
    <actuator name="left_wheel_back_motor">
      <hardwareInterface>hardware_interface/VelocityJointInterface</hardwareInterface>
      <mechanicalReduction>1</mechanicalReduction>
    </actuator>
  </transmission>
  <gazebo reference="left_wheel_back">
    <mu1>0.9</mu1>
    <mu2>0.9</mu2>
  </gazebo>

  <link name="right_wheel_back">
    <inertial>
      <mass value="0.2"/>
      <origin rpy="1.5707963267948966 0 0" xyz="0 -0.021 0"/>
      <inertia ixx="0.00015875000000000004" ixy="0" ixz="0" iyy="0.00015875000000000004" iyz="0" izz="0.00025000000000000006"/>
    </inertial>
    <collision>
      <origin rpy="1.5707963267948966 0 0 " xyz="0 -0.021 0"/>
      <geometry>
        <cylinder length="0.045" radius="0.05"/>
      </geometry>
    </collision>
    <visual>
      <origin rpy="0 0 0.0" xyz="0 -0.021 0"/>
      <geometry>
        <mesh filename="file:///home/ty/f1test_ws/ar-tu-do/ros_ws/install/racer_description/share/racer_description/meshes/wheel.dae"/>
      </geometry>
    </visual>
  </link>
  <gazebo reference="right_wheel_back">
    <material>Gazebo/Black</material>
  </gazebo>
  <joint name="right_wheel_back_hinge" type="continuous">
    <parent link="chassis"/>
    <child link="right_wheel_back"/>
    <origin rpy="0 0 0" xyz="-0.16 -0.1055 0"/>
    <axis rpy="0 0 0" xyz="0 1 0"/>
    <limit effort="20" velocity="500"/>
    <joint_properties damping="0.0" friction="0.0"/>
  </joint>
  <transmission name="right_wheel_back_transmission">
    <type>transmission_interface/SimpleTransmission</type>
    <joint name="right_wheel_back_hinge">
      <hardwareInterface>hardware_interface/VelocityJointInterface</hardwareInterface>
    </joint>
    <actuator name="right_wheel_back_motor">
      <hardwareInterface>hardware_interface/VelocityJointInterface</hardwareInterface>
      <mechanicalReduction>1</mechanicalReduction>
    </actuator>
  </transmission>
  <gazebo reference="right_wheel_back">
    <mu1>0.9</mu1>
    <mu2>0.9</mu2>
  </gazebo>

  <link name="left_steering">
    <inertial>
      <mass value="0.07"/>
      <origin rpy="0 0 0" xyz="0 0 0"/>
      <inertia ixx="4.666666666666667e-06" ixy="0" ixz="0" iyy="4.666666666666667e-06" iyz="0" izz="4.666666666666667e-06"/>
    </inertial>
    <visual>
      <origin rpy="0 0 0" xyz="0 0 0"/>
      <geometry>
        <sphere radius="0.01"/>
      </geometry>
    </visual>
  </link>
  <gazebo reference="left_steering">
    <material>Gazebo/Grey</material>
  </gazebo>
  <joint name="left_steering_hinge" type="revolute">
    <origin rpy="0 0 0" xyz="0.16 0.1055 0"/>
    <parent link="chassis"/>
    <child link="left_steering"/>
    <axis xyz="0 0 1"/>
    <limit effort="10" lower="-1.0" upper="1.0" velocity="100"/>
  </joint>
  <transmission name="left_steering_hinge_transmission">
    <type>transmission_interface/SimpleTransmission</type>
    <joint name="left_steering_hinge">
      <hardwareInterface>hardware_interface/PositionJointInterface</hardwareInterface>
    </joint>
    <actuator name="left_steering_hinge_motor">
      <hardwareInterface>hardware_interface/PositionJointInterface</hardwareInterface>
      <mechanicalReduction>1</mechanicalReduction>
    </actuator>
  </transmission>

  <link name="right_steering">
    <inertial>
      <mass value="0.07"/>
      <origin rpy="0 0 0" xyz="0 0 0"/>
      <inertia ixx="4.666666666666667e-06" ixy="0" ixz="0" iyy="4.666666666666667e-06" iyz="0" izz="4.666666666666667e-06"/>
    </inertial>
    <visual>
      <origin rpy="0 0 0" xyz="0 0 0"/>
      <geometry>
        <sphere radius="0.01"/>
      </geometry>
    </visual>
  </link>
  <gazebo reference="right_steering">
    <material>Gazebo/Grey</material>
  </gazebo>
  <joint name="right_steering_hinge" type="revolute">
    <origin rpy="0 0 0" xyz="0.16 -0.1055 0"/>
    <parent link="chassis"/>
    <child link="right_steering"/>
    <axis xyz="0 0 1"/>
    <limit effort="10" lower="-1.0" upper="1.0" velocity="100"/>
  </joint>
  <transmission name="right_steering_hinge_transmission">
    <type>transmission_interface/SimpleTransmission</type>
    <joint name="right_steering_hinge">
      <hardwareInterface>hardware_interface/PositionJointInterface</hardwareInterface>
    </joint>
    <actuator name="right_steering_hinge_motor">
      <hardwareInterface>hardware_interface/PositionJointInterface</hardwareInterface>
      <mechanicalReduction>1</mechanicalReduction>
    </actuator>
  </transmission>

  <link name="camera">
    <inertial>
      <mass value="0.1"/>
      <origin rpy="0 0 0" xyz="0 0 0.0225"/>
      <inertia ixx="0.0002483333333333334" ixy="0" ixz="0" iyy="0.0002483333333333334" iyz="0" izz="1.5e-05"/>
    </inertial>
    <collision>
      <origin rpy="0 0 0" xyz="0 0 0"/>
      <geometry>
        <box size="0.03 0.17 0.03"/>
      </geometry>
    </collision>
    <visual>
      <origin rpy="0 0 0" xyz="0 0 0"/>
      <geometry>
        <mesh filename="file:///home/ty/f1test_ws/ar-tu-do/ros_ws/install/racer_description/share/racer_description/meshes/ZED.dae"/>
      </geometry>
    </visual>
  </link>
  <gazebo reference="camera">
    <material>Gazebo/Red</material>
  </gazebo>
  <joint name="camera_joint" type="fixed">
    <axis xyz="0 1 0"/>
    <origin rpy="0 0 0" xyz="0.21 0 0.095"/>
    <parent link="chassis"/>
    <child link="camera"/>
  </joint>

  <link name="laser">
    <inertial>
      <mass value="0.1"/>
      <origin rpy="0 0 0" xyz="0 0 0.0225"/>
      <inertia ixx="0.00016666666666666672" ixy="0" ixz="0" iyy="0.00016666666666666672" iyz="0" izz="0.00016666666666666672"/>
    </inertial>
    <collision>
      <origin rpy="0 0 0" xyz="0 0 0.0225"/>
      <geometry>
        <box size="0.1 0.1 0.1"/>
      </geometry>
    </collision>
    <visual>
      <origin rpy="0 0 0" xyz="0 0 0.0225"/>
      <geometry>
        <mesh filename="file:///home/ty/f1test_ws/ar-tu-do/ros_ws/install/racer_description/share/racer_description/meshes/hokuyo.dae"/>
      </geometry>
    </visual>
  </link>
  <gazebo reference="laser">
    <material>Gazebo/Green</material>
  </gazebo>
  <joint name="laser_joint" type="fixed">
    <axis xyz="0 1 0"/>
    <origin rpy="0 0 0" xyz="0.21 0 0.135"/>
    <parent link="chassis"/>
    <child link="laser"/>
  </joint>

  <link name="imu_link"/>
  <joint name="imu_joint" type="fixed">
    <axis xyz="0 1 0"/>
    <origin rpy="0 0 0" xyz="0 0 0.135"/>
    <parent link="chassis"/>
    <child link="imu_link"/>
  </joint>

</robot>
